2022-08-10 09:36:02,696: ERROR Invalid Manger Credential
Traceback (most recent call last):
  File "C:\Users\wemimo.fo\AppData\Local\Packages\PythonSoftwareFoundation.Python.3.9_qbz5n2kfra8p0\LocalCache\local-packages\Python39\site-packages\django\db\backends\utils.py", line 89, in _execute
    return self.cursor.execute(sql, params)
  File "C:\Users\wemimo.fo\AppData\Local\Packages\PythonSoftwareFoundation.Python.3.9_qbz5n2kfra8p0\LocalCache\local-packages\Python39\site-packages\django\db\backends\sqlite3\base.py", line 477, in execute
    return Database.Cursor.execute(self, query, params)
sqlite3.OperationalError: no such table: user

The above exception was the direct cause of the following exception:

Traceback (most recent call last):
  File "C:\Users\wemimo.fo\Documents\ApiProject\django_project\api\views.py", line 30, in post
    valid = serializer.is_valid(raise_exception=True)
  File "C:\Users\wemimo.fo\AppData\Local\Packages\PythonSoftwareFoundation.Python.3.9_qbz5n2kfra8p0\LocalCache\local-packages\Python39\site-packages\rest_framework\serializers.py", line 227, in is_valid
    self._validated_data = self.run_validation(self.initial_data)
  File "C:\Users\wemimo.fo\AppData\Local\Packages\PythonSoftwareFoundation.Python.3.9_qbz5n2kfra8p0\LocalCache\local-packages\Python39\site-packages\rest_framework\serializers.py", line 429, in run_validation
    value = self.validate(value)
  File "C:\Users\wemimo.fo\Documents\ApiProject\django_project\api\serializers.py", line 65, in validate
    user = authenticate(email=email, password=password)
  File "C:\Users\wemimo.fo\AppData\Local\Packages\PythonSoftwareFoundation.Python.3.9_qbz5n2kfra8p0\LocalCache\local-packages\Python39\site-packages\django\views\decorators\debug.py", line 42, in sensitive_variables_wrapper
    return func(*func_args, **func_kwargs)
  File "C:\Users\wemimo.fo\AppData\Local\Packages\PythonSoftwareFoundation.Python.3.9_qbz5n2kfra8p0\LocalCache\local-packages\Python39\site-packages\django\contrib\auth\__init__.py", line 77, in authenticate
    user = backend.authenticate(request, **credentials)
  File "C:\Users\wemimo.fo\AppData\Local\Packages\PythonSoftwareFoundation.Python.3.9_qbz5n2kfra8p0\LocalCache\local-packages\Python39\site-packages\django\contrib\auth\backends.py", line 42, in authenticate
    user = UserModel._default_manager.get_by_natural_key(username)
  File "C:\Users\wemimo.fo\AppData\Local\Packages\PythonSoftwareFoundation.Python.3.9_qbz5n2kfra8p0\LocalCache\local-packages\Python39\site-packages\django\contrib\auth\base_user.py", line 46, in get_by_natural_key
    return self.get(**{self.model.USERNAME_FIELD: username})
  File "C:\Users\wemimo.fo\AppData\Local\Packages\PythonSoftwareFoundation.Python.3.9_qbz5n2kfra8p0\LocalCache\local-packages\Python39\site-packages\django\db\models\manager.py", line 85, in manager_method
    return getattr(self.get_queryset(), name)(*args, **kwargs)
  File "C:\Users\wemimo.fo\AppData\Local\Packages\PythonSoftwareFoundation.Python.3.9_qbz5n2kfra8p0\LocalCache\local-packages\Python39\site-packages\django\db\models\query.py", line 492, in get
    num = len(clone)
  File "C:\Users\wemimo.fo\AppData\Local\Packages\PythonSoftwareFoundation.Python.3.9_qbz5n2kfra8p0\LocalCache\local-packages\Python39\site-packages\django\db\models\query.py", line 302, in __len__
    self._fetch_all()
  File "C:\Users\wemimo.fo\AppData\Local\Packages\PythonSoftwareFoundation.Python.3.9_qbz5n2kfra8p0\LocalCache\local-packages\Python39\site-packages\django\db\models\query.py", line 1507, in _fetch_all
    self._result_cache = list(self._iterable_class(self))
  File "C:\Users\wemimo.fo\AppData\Local\Packages\PythonSoftwareFoundation.Python.3.9_qbz5n2kfra8p0\LocalCache\local-packages\Python39\site-packages\django\db\models\query.py", line 57, in __iter__
    results = compiler.execute_sql(
  File "C:\Users\wemimo.fo\AppData\Local\Packages\PythonSoftwareFoundation.Python.3.9_qbz5n2kfra8p0\LocalCache\local-packages\Python39\site-packages\django\db\models\sql\compiler.py", line 1361, in execute_sql
    cursor.execute(sql, params)
  File "C:\Users\wemimo.fo\AppData\Local\Packages\PythonSoftwareFoundation.Python.3.9_qbz5n2kfra8p0\LocalCache\local-packages\Python39\site-packages\django\db\backends\utils.py", line 103, in execute
    return super().execute(sql, params)
  File "C:\Users\wemimo.fo\AppData\Local\Packages\PythonSoftwareFoundation.Python.3.9_qbz5n2kfra8p0\LocalCache\local-packages\Python39\site-packages\django\db\backends\utils.py", line 67, in execute
    return self._execute_with_wrappers(
  File "C:\Users\wemimo.fo\AppData\Local\Packages\PythonSoftwareFoundation.Python.3.9_qbz5n2kfra8p0\LocalCache\local-packages\Python39\site-packages\django\db\backends\utils.py", line 80, in _execute_with_wrappers
    return executor(sql, params, many, context)
  File "C:\Users\wemimo.fo\AppData\Local\Packages\PythonSoftwareFoundation.Python.3.9_qbz5n2kfra8p0\LocalCache\local-packages\Python39\site-packages\django\db\backends\utils.py", line 89, in _execute
    return self.cursor.execute(sql, params)
  File "C:\Users\wemimo.fo\AppData\Local\Packages\PythonSoftwareFoundation.Python.3.9_qbz5n2kfra8p0\LocalCache\local-packages\Python39\site-packages\django\db\utils.py", line 91, in __exit__
    raise dj_exc_value.with_traceback(traceback) from exc_value
  File "C:\Users\wemimo.fo\AppData\Local\Packages\PythonSoftwareFoundation.Python.3.9_qbz5n2kfra8p0\LocalCache\local-packages\Python39\site-packages\django\db\backends\utils.py", line 89, in _execute
    return self.cursor.execute(sql, params)
  File "C:\Users\wemimo.fo\AppData\Local\Packages\PythonSoftwareFoundation.Python.3.9_qbz5n2kfra8p0\LocalCache\local-packages\Python39\site-packages\django\db\backends\sqlite3\base.py", line 477, in execute
    return Database.Cursor.execute(self, query, params)
django.db.utils.OperationalError: no such table: user
2022-08-10 10:26:06,286: ERROR Registration Unsuccessful
Traceback (most recent call last):
  File "C:\Users\wemimo.fo\Documents\ApiProject\django_project\api\views.py", line 69, in post
    serializer.save()
  File "C:\Users\wemimo.fo\AppData\Local\Packages\PythonSoftwareFoundation.Python.3.9_qbz5n2kfra8p0\LocalCache\local-packages\Python39\site-packages\rest_framework\serializers.py", line 212, in save
    self.instance = self.create(validated_data)
  File "C:\Users\wemimo.fo\Documents\ApiProject\django_project\api\serializers.py", line 25, in create
    auth_user = User.objects.create_user(**validated_data)
  File "C:\Users\wemimo.fo\Documents\ApiProject\django_project\api\managers.py", line 18, in create_user
    user = self.model(email=email, **extra_fields)
  File "C:\Users\wemimo.fo\AppData\Local\Packages\PythonSoftwareFoundation.Python.3.9_qbz5n2kfra8p0\LocalCache\local-packages\Python39\site-packages\django\db\models\base.py", line 559, in __init__
    raise TypeError(
TypeError: User() got an unexpected keyword argument 'rpassword'
2022-08-10 10:27:47,133: ERROR Registration Unsuccessful
Traceback (most recent call last):
  File "C:\Users\wemimo.fo\Documents\ApiProject\django_project\api\views.py", line 69, in post
    serializer.save()
  File "C:\Users\wemimo.fo\AppData\Local\Packages\PythonSoftwareFoundation.Python.3.9_qbz5n2kfra8p0\LocalCache\local-packages\Python39\site-packages\rest_framework\serializers.py", line 212, in save
    self.instance = self.create(validated_data)
  File "C:\Users\wemimo.fo\Documents\ApiProject\django_project\api\serializers.py", line 29, in create
    auth_user = User.objects.create_user(**validated_data)
  File "C:\Users\wemimo.fo\Documents\ApiProject\django_project\api\managers.py", line 18, in create_user
    user = self.model(email=email, **extra_fields)
  File "C:\Users\wemimo.fo\AppData\Local\Packages\PythonSoftwareFoundation.Python.3.9_qbz5n2kfra8p0\LocalCache\local-packages\Python39\site-packages\django\db\models\base.py", line 559, in __init__
    raise TypeError(
TypeError: User() got an unexpected keyword argument 'rpassword'
2022-08-10 10:28:09,719: ERROR Registration Unsuccessful
Traceback (most recent call last):
  File "C:\Users\wemimo.fo\Documents\ApiProject\django_project\api\views.py", line 69, in post
    serializer.save()
  File "C:\Users\wemimo.fo\AppData\Local\Packages\PythonSoftwareFoundation.Python.3.9_qbz5n2kfra8p0\LocalCache\local-packages\Python39\site-packages\rest_framework\serializers.py", line 212, in save
    self.instance = self.create(validated_data)
  File "C:\Users\wemimo.fo\Documents\ApiProject\django_project\api\serializers.py", line 29, in create
    auth_user = User.objects.create_user(**validated_data)
  File "C:\Users\wemimo.fo\Documents\ApiProject\django_project\api\managers.py", line 18, in create_user
    user = self.model(email=email, **extra_fields)
  File "C:\Users\wemimo.fo\AppData\Local\Packages\PythonSoftwareFoundation.Python.3.9_qbz5n2kfra8p0\LocalCache\local-packages\Python39\site-packages\django\db\models\base.py", line 559, in __init__
    raise TypeError(
TypeError: User() got an unexpected keyword argument 'rpassword'
2022-08-10 10:28:12,723: ERROR Registration Unsuccessful
Traceback (most recent call last):
  File "C:\Users\wemimo.fo\Documents\ApiProject\django_project\api\views.py", line 66, in post
    valid = serializer.is_valid(raise_exception=True)
  File "C:\Users\wemimo.fo\AppData\Local\Packages\PythonSoftwareFoundation.Python.3.9_qbz5n2kfra8p0\LocalCache\local-packages\Python39\site-packages\rest_framework\serializers.py", line 235, in is_valid
    raise ValidationError(self.errors)
rest_framework.exceptions.ValidationError: {'email': [ErrorDetail(string='Enter a valid email address.', code='invalid')], 'password': [ErrorDetail(string='This field may not be blank.', code='blank')]}
2022-08-11 09:36:14,204: ERROR Registration Unsuccessful
Traceback (most recent call last):
  File "C:\Users\wemimo.fo\AppData\Local\Packages\PythonSoftwareFoundation.Python.3.9_qbz5n2kfra8p0\LocalCache\local-packages\Python39\site-packages\django\db\backends\utils.py", line 89, in _execute
    return self.cursor.execute(sql, params)
  File "C:\Users\wemimo.fo\AppData\Local\Packages\PythonSoftwareFoundation.Python.3.9_qbz5n2kfra8p0\LocalCache\local-packages\Python39\site-packages\django\db\backends\sqlite3\base.py", line 477, in execute
    return Database.Cursor.execute(self, query, params)
sqlite3.OperationalError: no such table: user

The above exception was the direct cause of the following exception:

Traceback (most recent call last):
  File "C:\Users\wemimo.fo\Documents\ApiProject\django_project\api\views.py", line 66, in post
    valid = serializer.is_valid(raise_exception=True)
  File "C:\Users\wemimo.fo\AppData\Local\Packages\PythonSoftwareFoundation.Python.3.9_qbz5n2kfra8p0\LocalCache\local-packages\Python39\site-packages\rest_framework\serializers.py", line 227, in is_valid
    self._validated_data = self.run_validation(self.initial_data)
  File "C:\Users\wemimo.fo\AppData\Local\Packages\PythonSoftwareFoundation.Python.3.9_qbz5n2kfra8p0\LocalCache\local-packages\Python39\site-packages\rest_framework\serializers.py", line 426, in run_validation
    value = self.to_internal_value(data)
  File "C:\Users\wemimo.fo\AppData\Local\Packages\PythonSoftwareFoundation.Python.3.9_qbz5n2kfra8p0\LocalCache\local-packages\Python39\site-packages\rest_framework\serializers.py", line 483, in to_internal_value
    validated_value = field.run_validation(primitive_value)
  File "C:\Users\wemimo.fo\AppData\Local\Packages\PythonSoftwareFoundation.Python.3.9_qbz5n2kfra8p0\LocalCache\local-packages\Python39\site-packages\rest_framework\fields.py", line 799, in run_validation
    return super().run_validation(data)
  File "C:\Users\wemimo.fo\AppData\Local\Packages\PythonSoftwareFoundation.Python.3.9_qbz5n2kfra8p0\LocalCache\local-packages\Python39\site-packages\rest_framework\fields.py", line 569, in run_validation
    self.run_validators(value)
  File "C:\Users\wemimo.fo\AppData\Local\Packages\PythonSoftwareFoundation.Python.3.9_qbz5n2kfra8p0\LocalCache\local-packages\Python39\site-packages\rest_framework\fields.py", line 591, in run_validators
    validator(value, self)
  File "C:\Users\wemimo.fo\AppData\Local\Packages\PythonSoftwareFoundation.Python.3.9_qbz5n2kfra8p0\LocalCache\local-packages\Python39\site-packages\rest_framework\validators.py", line 73, in __call__
    if qs_exists(queryset):
  File "C:\Users\wemimo.fo\AppData\Local\Packages\PythonSoftwareFoundation.Python.3.9_qbz5n2kfra8p0\LocalCache\local-packages\Python39\site-packages\rest_framework\validators.py", line 21, in qs_exists
    return queryset.exists()
  File "C:\Users\wemimo.fo\AppData\Local\Packages\PythonSoftwareFoundation.Python.3.9_qbz5n2kfra8p0\LocalCache\local-packages\Python39\site-packages\django\db\models\query.py", line 892, in exists
    return self.query.has_results(using=self.db)
  File "C:\Users\wemimo.fo\AppData\Local\Packages\PythonSoftwareFoundation.Python.3.9_qbz5n2kfra8p0\LocalCache\local-packages\Python39\site-packages\django\db\models\sql\query.py", line 589, in has_results
    return compiler.has_results()
  File "C:\Users\wemimo.fo\AppData\Local\Packages\PythonSoftwareFoundation.Python.3.9_qbz5n2kfra8p0\LocalCache\local-packages\Python39\site-packages\django\db\models\sql\compiler.py", line 1329, in has_results
    return bool(self.execute_sql(SINGLE))
  File "C:\Users\wemimo.fo\AppData\Local\Packages\PythonSoftwareFoundation.Python.3.9_qbz5n2kfra8p0\LocalCache\local-packages\Python39\site-packages\django\db\models\sql\compiler.py", line 1361, in execute_sql
    cursor.execute(sql, params)
  File "C:\Users\wemimo.fo\AppData\Local\Packages\PythonSoftwareFoundation.Python.3.9_qbz5n2kfra8p0\LocalCache\local-packages\Python39\site-packages\django\db\backends\utils.py", line 103, in execute
    return super().execute(sql, params)
  File "C:\Users\wemimo.fo\AppData\Local\Packages\PythonSoftwareFoundation.Python.3.9_qbz5n2kfra8p0\LocalCache\local-packages\Python39\site-packages\django\db\backends\utils.py", line 67, in execute
    return self._execute_with_wrappers(
  File "C:\Users\wemimo.fo\AppData\Local\Packages\PythonSoftwareFoundation.Python.3.9_qbz5n2kfra8p0\LocalCache\local-packages\Python39\site-packages\django\db\backends\utils.py", line 80, in _execute_with_wrappers
    return executor(sql, params, many, context)
  File "C:\Users\wemimo.fo\AppData\Local\Packages\PythonSoftwareFoundation.Python.3.9_qbz5n2kfra8p0\LocalCache\local-packages\Python39\site-packages\django\db\backends\utils.py", line 89, in _execute
    return self.cursor.execute(sql, params)
  File "C:\Users\wemimo.fo\AppData\Local\Packages\PythonSoftwareFoundation.Python.3.9_qbz5n2kfra8p0\LocalCache\local-packages\Python39\site-packages\django\db\utils.py", line 91, in __exit__
    raise dj_exc_value.with_traceback(traceback) from exc_value
  File "C:\Users\wemimo.fo\AppData\Local\Packages\PythonSoftwareFoundation.Python.3.9_qbz5n2kfra8p0\LocalCache\local-packages\Python39\site-packages\django\db\backends\utils.py", line 89, in _execute
    return self.cursor.execute(sql, params)
  File "C:\Users\wemimo.fo\AppData\Local\Packages\PythonSoftwareFoundation.Python.3.9_qbz5n2kfra8p0\LocalCache\local-packages\Python39\site-packages\django\db\backends\sqlite3\base.py", line 477, in execute
    return Database.Cursor.execute(self, query, params)
django.db.utils.OperationalError: no such table: user
